Workbook
Name _AA100000: #REF!
Name _Fill: #REF!
Name _LOC10: #REF!
Name _LOC11: #REF!
Name _LOC12: #REF!
Name _LOC13: #REF!
Name _LOC14: #REF!
Name _LOC15: #REF!
Name _LOC16: #REF!
Name _LOC17: #REF!
Name _LOC18: #REF!
Name _LOC19: #REF!
Name _LOC2: #REF!
Name _LOC20: #REF!
Name _LOC21: #REF!
Name _LOC22: #REF!
Name _LOC23: #REF!
Name _LOC24: #REF!
Name _LOC25: #REF!
Name _LOC26: #REF!
Name _LOC27: #REF!
Name _LOC28: #REF!
Name _LOC29: #REF!
Name _LOC3: #REF!
Name _LOC30: #REF!
Name _LOC31: #REF!
Name _LOC32: #REF!
Name _LOC33: #REF!
Name _LOC34: #REF!
Name _LOC35: #REF!
Name _LOC36: #REF!
Name _LOC37: #REF!
Name _LOC38: #REF!
Name _LOC39: #REF!
Name _LOC4: #REF!
Name _LOC40: #REF!
Name _LOC41: #REF!
Name _LOC42: #REF!
Name _LOC5: #REF!
Name _LOC6: #REF!
Name _LOC7: #REF!
Name _LOC8: #REF!
Name _LOC9: #REF!
Name _R: #REF!
Name AAA: #REF!
Name AC: #REF!
Name AL: #REF!
Name Área_impressão_IM: #REF!
Name B.01.05.10.10: #REF!
Name CD: #REF!
Name CP: #REF!
Name CS: #REF!
Name CT: #REF!
Name EV: #REF!
Name IC: #REF!
Name IMPR: #REF!
Name IMPR1: #REF!
Name IS: #REF!
Name LB: #REF!
Name MACROS: #REF!

Sheet DADOS GERAIS
B2: DADOS GERAIS
B8: Secretaria de Atenção Especializada à Saúde
B9: =C15 -> Policlínica - Área Construída: 3.213,00 m²
B11: Bancos:
B12: SINAPI (11/2023) - CPOS/CDHU (11/2023) - SBC (11/2023) - ORSE (11/2023) - SEINFRA (028) - IOPES (11/2023) - CAERN (11/2023) - EMOP (11/2023)
B15: Obra: | C15: Policlínica - Área Construída: 3.213,00 m²
B16: Local: | C16: Ministério da Saúde - Departamento de Atenção Hospitalar Domiciliar e de Urgência
B17: Região: | C17: SP
B18: Data Base: | C18: 45231
B19: BDI Geral (%): | C19: ='BDI DESONERADO'!E36 -> 0.24875249
B20: BDI Equipamentos (%): | C20: ='BDI DESONERADO'!F36 -> 0.16857591
B21: Área construída (m²): | C21: 3213
B22: Data: | C22: 09/05/2024
B23: Revisão: | C23: 03
B24: Responsável Técnico pelo Orçamento: | C24: Thaís Ferreira Pellaquim
B25: Cargo Responsável Técnico: | C25: Engenheira Civil - CREA MG 247749/D
B31: ________________________________________________________________________________
B32: =C24 -> Thaís Ferreira Pellaquim
B33: =C25 -> Engenheira Civil - CREA MG 247749/D

Sheet RESUMO
B2: PLANILHA RESUMO
B8: ='DADOS GERAIS'!B8 -> Secretaria de Atenção Especializada à Saúde | D8: BDI Geral: | E8: Encargo Social Mensalista: | F8: ='DADOS GERAIS'!$B$22 -> Data:
B9: ='DADOS GERAIS'!B9 -> Policlínica - Área Construída: 3.213,00 m² | D9: ='DADOS GERAIS'!C19 -> 0.24875249 | E9: ='ENCARGOS SOCIAIS'!F56 -> 0.4757 | F9: ='DADOS GERAIS'!$C$22 -> 09/05/2024
B11: ='DADOS GERAIS'!B11 -> Bancos: | D11: BDI Equipamentos: | E11: Encargo Social Horista: | F11: ='DADOS GERAIS'!$B$23 -> Revisão:
B12: ='DADOS GERAIS'!B12 -> SINAPI (11/2023) - CPOS/CDHU (11/2023) - SBC (11/2023) - ORSE (11/2023) - SEINFRA (028) - IOPES (11/2023) - CAERN (11/2023) - EMOP (11/2023) | D12: ='DADOS GERAIS'!C20 -> 0.16857591 | E12: ='ENCARGOS SOCIAIS'!E56 -> 0.8555518 | F12: ='DADOS GERAIS'!$C$23 -> 03
B15: ITEM | C15: DESCRIÇÃO | E15: PREÇO | F15: %
B17: 1 | C17: {=INDEX('ORC. SINTÉTICO'!$E:$E,MATCH($B17,'ORC. SINTÉTICO'!$B:$B,0))} -> SERVIÇOS PRELIMINARES E INDIRETOS | E17: {=INDEX('ORC. SINTÉTICO'!$N:$N,MATCH($B17,'ORC. SINTÉTICO'!$B:$B,0))} -> 0 | F17: =IFERROR(E17/$E$41,"-") -> -
B18: 2 | C18: {=INDEX('ORC. SINTÉTICO'!$E:$E,MATCH($B18,'ORC. SINTÉTICO'!$B:$B,0))} -> FUNDAÇÃO | E18: {=INDEX('ORC. SINTÉTICO'!$N:$N,MATCH($B18,'ORC. SINTÉTICO'!$B:$B,0))} -> 0 | F18: =IFERROR(E18/$E$41,"-") -> -
B19: 3 | C19: {=INDEX('ORC. SINTÉTICO'!$E:$E,MATCH($B19,'ORC. SINTÉTICO'!$B:$B,0))} -> ESTRUTURA | E19: {=INDEX('ORC. SINTÉTICO'!$N:$N,MATCH($B19,'ORC. SINTÉTICO'!$B:$B,0))} -> 0 | F19: =IFERROR(E19/$E$41,"-") -> -
B20: 4 | C20: {=INDEX('ORC. SINTÉTICO'!$E:$E,MATCH($B20,'ORC. SINTÉTICO'!$B:$B,0))} -> ALVENARIA, VEDAÇÕES E DIVISÓRIAS | E20: {=INDEX('ORC. SINTÉTICO'!$N:$N,MATCH($B20,'ORC. SINTÉTICO'!$B:$B,0))} -> 0 | F20: =IFERROR(E20/$E$41,"-") -> -
B21: 5 | C21: {=INDEX('ORC. SINTÉTICO'!$E:$E,MATCH($B21,'ORC. SINTÉTICO'!$B:$B,0))} -> ESQUADRIAS | E21: {=INDEX('ORC. SINTÉTICO'!$N:$N,MATCH($B21,'ORC. SINTÉTICO'!$B:$B,0))} -> 0 | F21: =IFERROR(E21/$E$41,"-") -> -
B22: 6 | C22: {=INDEX('ORC. SINTÉTICO'!$E:$E,MATCH($B22,'ORC. SINTÉTICO'!$B:$B,0))} -> COBERTURA | E22: {=INDEX('ORC. SINTÉTICO'!$N:$N,MATCH($B22,'ORC. SINTÉTICO'!$B:$B,0))} -> 0 | F22: =IFERROR(E22/$E$41,"-") -> -
B23: 7 | C23: {=INDEX('ORC. SINTÉTICO'!$E:$E,MATCH($B23,'ORC. SINTÉTICO'!$B:$B,0))} -> IMPERMEABILIZAÇÃO | E23: {=INDEX('ORC. SINTÉTICO'!$N:$N,MATCH($B23,'ORC. SINTÉTICO'!$B:$B,0))} -> 0 | F23: =IFERROR(E23/$E$41,"-") -> -
B24: 8 | C24: {=INDEX('ORC. SINTÉTICO'!$E:$E,MATCH($B24,'ORC. SINTÉTICO'!$B:$B,0))} -> REVESTIMENTO DE PAREDE | E24: {=INDEX('ORC. SINTÉTICO'!$N:$N,MATCH($B24,'ORC. SINTÉTICO'!$B:$B,0))} -> 0 | F24: =IFERROR(E24/$E$41,"-") -> -
B25: 9 | C25: {=INDEX('ORC. SINTÉTICO'!$E:$E,MATCH($B25,'ORC. SINTÉTICO'!$B:$B,0))} -> REVESTIMENTO DE PISO INTERNO | E25: {=INDEX('ORC. SINTÉTICO'!$N:$N,MATCH($B25,'ORC. SINTÉTICO'!$B:$B,0))} -> 0 | F25: =IFERROR(E25/$E$41,"-") -> -
B26: 10 | C26: {=INDEX('ORC. SINTÉTICO'!$E:$E,MATCH($B26,'ORC. SINTÉTICO'!$B:$B,0))} -> REVESTIMENTO DE PISO EXTERNO | E26: {=INDEX('ORC. SINTÉTICO'!$N:$N,MATCH($B26,'ORC. SINTÉTICO'!$B:$B,0))} -> 0 | F26: =IFERROR(E26/$E$41,"-") -> -
B27: 11 | C27: {=INDEX('ORC. SINTÉTICO'!$E:$E,MATCH($B27,'ORC. SINTÉTICO'!$B:$B,0))} -> REVESTIMENTO DE TETO | E27: {=INDEX('ORC. SINTÉTICO'!$N:$N,MATCH($B27,'ORC. SINTÉTICO'!$B:$B,0))} -> 0 | F27: =IFERROR(E27/$E$41,"-") -> -
B28: 12 | C28: {=INDEX('ORC. SINTÉTICO'!$E:$E,MATCH($B28,'ORC. SINTÉTICO'!$B:$B,0))} -> FACHADA | E28: {=INDEX('ORC. SINTÉTICO'!$N:$N,MATCH($B28,'ORC. SINTÉTICO'!$B:$B,0))} -> 0 | F28: =IFERROR(E28/$E$41,"-") -> -
... B39: 23 | C39: {=INDEX('ORC. SINTÉTICO'!$E:$E,MATCH($B39,'ORC. SINTÉTICO'!$B:$B,0))} -> SERVIÇOS COMPLEMENTARES | E39: {=INDEX('ORC. SINTÉTICO'!$N:$N,MATCH($B39,'ORC. SINTÉTICO'!$B:$B,0))} -> 0 | F39: =IFERROR(E39/$E$41,"-") -> -
B41: TOTAL | E41: =SUBTOTAL(9,E17:E39) -> 0 | F41: =SUBTOTAL(9,F17:F39) -> 0
B43: Notas:
B44: Estão exclusos do escopo: Calçada externa, piso intertravado, administração local, movimentação de terra, bate-macas, protetores de parede e portas, pingadeiras, mobiliário e equipamentos.
B51: ________________________________________________________________________________
B52: ='DADOS GERAIS'!C24 -> Thaís Ferreira Pellaquim
B53: ='DADOS GERAIS'!C25 -> Engenheira Civil - CREA MG 247749/D

Sheet ORC. SINTÉTICO
B2: PLANILHA DE ORÇAMENTO SINTÉTICO
B8: ='DADOS GERAIS'!$B$8 -> Secretaria de Atenção Especializada à Saúde | K8: =RESUMO!D8 -> BDI Geral: | M8: =RESUMO!E8 -> Encargo Social Mensalista: | O8: ='DADOS GERAIS'!$B$22 -> Data:
B9: ='DADOS GERAIS'!$B$9 -> Policlínica - Área Construída: 3.213,00 m² | K9: =RESUMO!D9 -> 0.24875249 | M9: =RESUMO!E9 -> 0.4757 | O9: ='DADOS GERAIS'!$C$22 -> 09/05/2024
B11: =RESUMO!B11 -> Bancos: | K11: =RESUMO!D11 -> BDI Equipamentos: | M11: =RESUMO!E11 -> Encargo Social Horista: | O11: ='DADOS GERAIS'!$B$23 -> Revisão:
B12: ='DADOS GERAIS'!$B$12 -> SINAPI (11/2023) - CPOS/CDHU (11/2023) - SBC (11/2023) - ORSE (11/2023) - SEINFRA (028) - IOPES (11/2023) - CAERN (11/2023) - EMOP (11/2023) | K12: =RESUMO!D12 -> 0.16857591 | M12: =RESUMO!E12 -> 0.8555518 | O12: ='DADOS GERAIS'!$C$23 -> 03
B15: Item | C15: Código | D15: Banco | E15: Descrição | F15: Und | G15: Quant. | H15: Valor Unit | I15: Valor Unit com BDI | L15: Total | O15: Peso (%)
I16: M. O. | J16: MAT. | K16: Total | L16: M. O. | M16: MAT. | N16: Total
B18: 1 | E18: SERVIÇOS PRELIMINARES E INDIRETOS
B19: 1.1 | E19: CANTEIRO DE OBRAS
B20: 1.1.1 | C20: 02.02.150 | D20: CPOS/CDHU | E20: LOCAÇÃO DE CONTAINER TIPO DEPÓSITO - ÁREA MÍNIMA DE 13,80 M² | F20: unxmês | G20: 32
B21: 1.1.2 | C21: 93582 | D21: SINAPI | E21: EXECUÇÃO DE CENTRAL DE ARMADURA EM CANTEIRO DE OBRA, NÃO INCLUSO MOBILIÁRIO E EQUIPAMENTOS. AF_04/2016 | F21: m² | G21: 14
B22: 1.1.3 | C22: 93583 | D22: SINAPI | E22: EXECUÇÃO DE CENTRAL DE FÔRMAS, PRODUÇÃO DE ARGAMASSA OU CONCRETO EM CANTEIRO DE OBRA, NÃO INCLUSO MOBILIÁRIO E EQUIPAMENTOS. AF_04/2016 | F22: m² | G22: 14
B23: 1.1.4 | C23: 02.02.130 | D23: CPOS/CDHU | E23: LOCAÇÃO DE CONTAINER TIPO ESCRITÓRIO COM 1 VASO SANITÁRIO, 1 LAVATÓRIO E 1 PONTO PARA CHUVEIRO - ÁREA MÍNIMA DE 13,80 M² | F23: unxmês | G23: 16
B24: 1.1.5 | C24: 02.02.160 | D24: CPOS/CDHU | E24: LOCAÇÃO DE CONTAINER TIPO GUARITA - ÁREA MÍNIMA DE 4,60 M² | F24: unxmês | G24: 16
B25: 1.1.6 | C25: 93210 | D25: SINAPI | E25: EXECUÇÃO DE REFEITÓRIO EM CANTEIRO DE OBRA EM CHAPA DE MADEIRA COMPENSADA, NÃO INCLUSO MOBILIÁRIO E EQUIPAMENTOS. AF_02/2016 | F25: m² | G25: 90
B26: 1.1.7 | C26: 02.02.140 | D26: CPOS/CDHU | E26: LOCAÇÃO DE CONTAINER TIPO SANITÁRIO COM 2 VASOS SANITÁRIOS, 2 LAVATÓRIOS, 2 MICTÓRIOS E 4 PONTOS PARA CHUVEIRO - ÁREA MÍNIMA DE 13,80 M² | F26: unxmês | G26: 64
B27: 1.1.8 | C27: 95648 | D27: SINAPI | E27: KIT CAVALETE PARA MEDIÇÃO DE ÁGUA - ENTRADA INDIVIDUALIZADA, EM CPVC DN 28 (1"), PARA 1 MEDIDOR - FORNECIMENTO E INSTALAÇÃO (EXCLUSIVE HIDRÔMETRO). AF_11/2016 | F27: UN | G27: 1
B28: 1.1.9 | C28: 95673 | D28: SINAPI | E28: HIDRÔMETRO DN 20 (½), 1,5 M³/H  FORNECIMENTO E INSTALAÇÃO. AF_11/2016 | F28: UN | G28: 1
B29: 1.1.10 | C29: 101509 | D29: SINAPI | E29: ENTRADA DE ENERGIA ELÉTRICA, AÉREA, TRIFÁSICA, COM CAIXA DE EMBUTIR, CABO DE 10 MM2 E DISJUNTOR DIN 50A (NÃO INCLUSO O POSTE DE CONCRETO). AF_07/2020_PS | F29: UN | G29: 1
B30: 1.1.11 | C30: 103689 | D30: SINAPI | E30: FORNECIMENTO E INSTALAÇÃO DE PLACA DE OBRA COM CHAPA GALVANIZADA E ESTRUTURA DE MADEIRA. AF_03/2022_PS | F30: m² | G30: 6
B31: 1.1.12 | C31: 93214 | D31: SINAPI | E31: EXECUÇÃO DE RESERVATÓRIO ELEVADO DE ÁGUA (1000 LITROS) EM CANTEIRO DE OBRA, APOIADO EM ESTRUTURA DE MADEIRA. AF_02/2016_PA | F31: UN | G31: 1
... B33: 1.1.14 | C33: 98459 | D33: SINAPI | E33: TAPUME COM TELHA METÁLICA. AF_05/2018 | F33: m² | G33: 640
B34: 1.2 | E34: MOBILIZAÇÃO E DESMOBILIZAÇÃO
B35: 1.2.1 | C35: 012689 | D35: SBC | E35: MOBILIZACAO E DESMOBILIZACAO DE CANTEIRO | F35: UN | G35: 1
B36: 1.2.2 | C36: 021101 | D36: SBC | E36: MOBILIZACAO/DESMOBILIZACAO DE EQUIP. E MO | F36: UN | G36: 1
B37: 1.3 | E37: EQUIPAMENTOS DE APOIO
B38: 1.3.1 | C38: CPU1926 | D38: Próprio | E38: LOCACAO DE ANDAIME METALICO TIPO FACHADEIRO, PECAS COM APROXIMADAMENTE 1,20 M DE LARGURA E 2,0 M DE ALTURA, INCLUINDO DIAGONAIS EM X, BARRAS DE LIGACAO, SAPATAS E DEMAIS ITENS NECESSARIOS A MONTAGEM, INCLUSIVE MONTAGEM E DESMONTAGEM | F38: M2XMÊS | G38: 5405.4
B39: 1.4 | E39: ADMINISTRAÇÃO LOCAL
B40: 1.4.1 | C40: 93565 | D40: SINAPI | E40: ENGENHEIRO CIVIL DE OBRA JUNIOR COM ENCARGOS COMPLEMENTARES | F40: MES | G40: 13
B41: 1.4.2 | C41: 93572 | D41: SINAPI | E41: ENCARREGADO GERAL DE OBRAS COM ENCARGOS COMPLEMENTARES | F41: MES | G41: 16
B42: 1.4.3 | C42: 101460 | D42: SINAPI | E42: VIGIA DIURNO COM ENCARGOS COMPLEMENTARES | F42: MES | G42: 16
B43: 1.4.4 | C43: 88326 | D43: SINAPI | E43: VIGIA NOTURNO COM ENCARGOS COMPLEMENTARES | F43: H | G43: 2560
B44: 2 | E44: FUNDAÇÃO
B45: 2.1 | C45: 99059 | D45: SINAPI | E45: LOCACAO CONVENCIONAL DE OBRA, UTILIZANDO GABARITO DE TÁBUAS CORRIDAS PONTALETADAS A CADA 2,00M - 2 UTILIZAÇÕES. AF_10/2018 | F45: M | G45: 224.5
B46: 2.2 | C46: 93358 | D46: SINAPI | E46: ESCAVAÇÃO MANUAL DE VALA COM PROFUNDIDADE MENOR OU IGUAL A 1,30 M. AF_02/2021 | F46: m³ | G46: 1314.95
B47: 2.3 | C47: 100324 | D47: SINAPI | E47: LASTRO COM MATERIAL GRANULAR (PEDRA BRITADA N.1 E PEDRA BRITADA N.2), APLICADO EM PISOS OU LAJES SOBRE SOLO, ESPESSURA DE *10 CM*. AF_07/2019 | F47: m³ | G47: 224.427
B48: 2.4 | C48: 96540 | D48: SINAPI | E48: FABRICAÇÃO, MONTAGEM E DESMONTAGEM DE FÔRMA PARA BLOCO DE COROAMENTO, EM CHAPA DE MADEIRA COMPENSADA RESINADA, E=17 MM, 4 UTILIZAÇÕES. AF_06/2017 | F48: m² | G48: 1709.7
B49: 2.5 | C49: 96543 | D49: SINAPI | E49: ARMAÇÃO DE BLOCO, VIGA BALDRAME E SAPATA UTILIZANDO AÇO CA-60 DE 5 MM - MONTAGEM. AF_06/2017 | F49: KG | G49: 1848.4
B50: 2.6 | C50: 96544 | D50: SINAPI | E50: ARMAÇÃO DE BLOCO, VIGA BALDRAME OU SAPATA UTILIZANDO AÇO CA-50 DE 6,3 MM - MONTAGEM. AF_06/2017 | F50: KG | G50: 14.8
B51: 2.7 | C51: 96545 | D51: SINAPI | E51: ARMAÇÃO DE BLOCO, VIGA BALDRAME OU SAPATA UTILIZANDO AÇO CA-50 DE 8 MM - MONTAGEM. AF_06/2017 | F51: KG | G51: 5867.6
...

Sheet CPUS
B2: COMPOSIÇÕES ANALÍTICAS COM PREÇO UNITÁRIO
B8: ='DADOS GERAIS'!$B$8 -> Secretaria de Atenção Especializada à Saúde | G8: =RESUMO!D8 -> BDI Geral: | I8: =RESUMO!E8 -> Encargo Social Mensalista: | K8: ='DADOS GERAIS'!$B$22 -> Data:
B9: ='DADOS GERAIS'!$B$9 -> Policlínica - Área Construída: 3.213,00 m² | G9: =RESUMO!D9 -> 0.24875249 | I9: =RESUMO!E9 -> 0.4757 | K9: ='DADOS GERAIS'!$C$22 -> 09/05/2024
B11: =RESUMO!B11 -> Bancos: | G11: =RESUMO!D11 -> BDI Equipamentos: | I11: =RESUMO!E11 -> Encargo Social Horista: | K11: ='DADOS GERAIS'!$B$23 -> Revisão:
B12: ='DADOS GERAIS'!$B$12 -> SINAPI (11/2023) - CPOS/CDHU (11/2023) - SBC (11/2023) - ORSE (11/2023) - SEINFRA (028) - IOPES (11/2023) - CAERN (11/2023) - EMOP (11/2023) | G12: =RESUMO!D12 -> 0.16857591 | I12: =RESUMO!E12 -> 0.8555518 | K12: ='DADOS GERAIS'!$C$23 -> 03
B15: Item | C15: Código | D15: Banco | E15: Descrição | G15: Und | H15: Quant. | I15: Porcent. | J15: Valor Unit | K15: Total
B17: Composições Principais
B18: 1.3.1 | C18: Código | D18: Banco | E18: Descrição | F18: Tipo | H18: Und | I18: Quant. | J18: Valor Unit | K18: Total
B19: Composição | C19: CPU1926 | D19: Próprio | E19: LOCACAO DE ANDAIME METALICO TIPO FACHADEIRO, PECAS COM APROXIMADAMENTE 1,20 M DE LARGURA E 2,0 M DE ALTURA, INCLUINDO DIAGONAIS EM X, BARRAS DE LIGACAO, SAPATAS E DEMAIS ITENS NECESSARIOS A MONTAGEM, INCLUSIVE MONTAGEM E DESMONTAGEM | F19: ASTU - ASSENTAMENTO DE TUBOS E PECAS | H19: M2XMÊS | I19: 1
B20: Composição Auxiliar | C20: 97063 | D20: SINAPI | E20: MONTAGEM E DESMONTAGEM DE ANDAIME MODULAR FACHADEIRO, COM PISO METÁLICO, PARA EDIFICAÇÕES COM MÚLTIPLOS PAVIMENTOS (EXCLUSIVE ANDAIME E LIMPEZA). AF_11/2017 | F20: SEDI - SERVIÇOS DIVERSOS | H20: m² | I20: 0.416
B21: Insumo | C21: 00020193 | D21: SINAPI | E21: LOCACAO DE ANDAIME METALICO TIPO FACHADEIRO, PECAS COM APROXIMADAMENTE 1,20 M DE LARGURA E 2,0 M DE ALTURA, INCLUINDO DIAGONAIS EM X, BARRAS DE LIGACAO, SAPATAS E DEMAIS ITENS NECESSARIOS A MONTAGEM (NAO INCLUI INSTALACAO) | F21: Equipamento | H21: M2/MES | I21: 1
F22: MO sem LS => | H22: LS => | I22: 0 | J22: MO com LS =>
F23: Valor do BDI => | I23: Valor com BDI =>
B25: 2.11 | C25: Código | D25: Banco | E25: Descrição | F25: Tipo | H25: Und | I25: Quant. | J25: Valor Unit | K25: Total
B26: Composição | C26: CPU2096 | D26: Próprio | E26: CONCRETAGEM DE BLOCOS DE COROAMENTO E VIGAS BALDRAMES, FCK 35 MPA, COM USO DE BOMBA  LANÇAMENTO, ADENSAMENTO E ACABAMENTO | F26: FUES - FUNDAÇÕES E ESTRUTURAS | H26: m³ | I26: 1
B27: Composição Auxiliar | C27: 90587 | D27: SINAPI | E27: VIBRADOR DE IMERSÃO, DIÂMETRO DE PONTEIRA 45MM, MOTOR ELÉTRICO TRIFÁSICO POTÊNCIA DE 2 CV - CHI DIURNO. AF_06/2015 | F27: CHOR - CUSTOS HORÁRIOS DE MÁQUINAS E EQUIPAMENTOS | H27: CHI | I27: 0.093
B28: Composição Auxiliar | C28: 88316 | D28: SINAPI | E28: SERVENTE COM ENCARGOS COMPLEMENTARES | F28: SEDI - SERVIÇOS DIVERSOS | H28: H | I28: 0.544
B29: Composição Auxiliar | C29: 88309 | D29: SINAPI | E29: PEDREIRO COM ENCARGOS COMPLEMENTARES | F29: SEDI - SERVIÇOS DIVERSOS | H29: H | I29: 0.363
B30: Composição Auxiliar | C30: 90586 | D30: SINAPI | E30: VIBRADOR DE IMERSÃO, DIÂMETRO DE PONTEIRA 45MM, MOTOR ELÉTRICO TRIFÁSICO POTÊNCIA DE 2 CV - CHP DIURNO. AF_06/2015 | F30: CHOR - CUSTOS HORÁRIOS DE MÁQUINAS E EQUIPAMENTOS | H30: CHP | I30: 0.088
B31: Insumo | C31: 00011145 | D31: SINAPI | E31: CONCRETO USINADO BOMBEAVEL, CLASSE DE RESISTENCIA C35, BRITA 0 E 1, SLUMP = 100 +/- 20 MM, COM BOMBEAMENTO (DISPONIBILIZACAO DE BOMBA), SEM O LANCAMENTO (NBR 8953) | F31: Material | H31: M³ | I31: 1.15
F32: MO sem LS => | H32: LS => | I32: 0 | J32: MO com LS =>
F33: Valor do BDI => | I33: Valor com BDI =>
B35: 3.1.8 | C35: Código | D35: Banco | E35: Descrição | F35: Tipo | H35: Und | I35: Quant. | J35: Valor Unit | K35: Total
B36: Composição | C36: CPU2097 | D36: Próprio | E36: CONCRETAGEM DE PILARES, FCK = 35 MPA, COM USO DE BOMBA - LANÇAMENTO, ADENSAMENTO E ACABAMENTO. AF_02/2022_PS | F36: FUES - FUNDAÇÕES E ESTRUTURAS | H36: m³ | I36: 1
B37: Composição Auxiliar | C37: 88309 | D37: SINAPI | E37: PEDREIRO COM ENCARGOS COMPLEMENTARES | F37: SEDI - SERVIÇOS DIVERSOS | H37: H | I37: 0.224
B38: Composição Auxiliar | C38: 90586 | D38: SINAPI | E38: VIBRADOR DE IMERSÃO, DIÂMETRO DE PONTEIRA 45MM, MOTOR ELÉTRICO TRIFÁSICO POTÊNCIA DE 2 CV - CHP DIURNO. AF_06/2015 | F38: CHOR - CUSTOS HORÁRIOS DE MÁQUINAS E EQUIPAMENTOS | H38: CHP | I38: 0.094
B39: Composição Auxiliar | C39: 90587 | D39: SINAPI | E39: VIBRADOR DE IMERSÃO, DIÂMETRO DE PONTEIRA 45MM, MOTOR ELÉTRICO TRIFÁSICO POTÊNCIA DE 2 CV - CHI DIURNO. AF_06/2015 | F39: CHOR - CUSTOS HORÁRIOS DE MÁQUINAS E EQUIPAMENTOS | H39: CHI | I39: 0.13
B40: Composição Auxiliar | C40: 88262 | D40: SINAPI | E40: CARPINTEIRO DE FORMAS COM ENCARGOS COMPLEMENTARES | F40: SEDI - SERVIÇOS DIVERSOS | H40: H | I40: 0.224
B41: Composição Auxiliar | C41: 88316 | D41: SINAPI | E41: SERVENTE COM ENCARGOS COMPLEMENTARES | F41: SEDI - SERVIÇOS DIVERSOS | H41: H | I41: 1.345
B42: Insumo | C42: 00011145 | D42: SINAPI | E42: CONCRETO USINADO BOMBEAVEL, CLASSE DE RESISTENCIA C35, BRITA 0 E 1, SLUMP = 100 +/- 20 MM, COM BOMBEAMENTO (DISPONIBILIZACAO DE BOMBA), SEM O LANCAMENTO (NBR 8953) | F42: Material | H42: M³ | I42: 1.103
F43: MO sem LS => | H43: LS => | I43: 0 | J43: MO com LS =>
F44: Valor do BDI => | I44: Valor com BDI =>
B46: 3.2.9 | C46: Código | D46: Banco | E46: Descrição | F46: Tipo | H46: Und | I46: Quant. | J46: Valor Unit | K46: Total
B47: Composição | C47: CPU2098 | D47: Próprio | E47: CONCRETAGEM DE LAJES EM EDIFICAÇÕES MULTIFAMILIARES FEITAS COM SISTEMA DE FÔRMAS MANUSEÁVEIS, COM CONCRETO USINADO BOMBEÁVEL FCK 35 MPA - LANÇAMENTO, ADENSAMENTO E ACABAMENTO. AF_10/2021 | F47: FUES - FUNDAÇÕES E ESTRUTURAS | H47: m³ | I47: 1
B48: Composição Auxiliar | C48: 88309 | D48: SINAPI | E48: PEDREIRO COM ENCARGOS COMPLEMENTARES | F48: SEDI - SERVIÇOS DIVERSOS | H48: H | I48: 0.556
B49: Composição Auxiliar | C49: 88262 | D49: SINAPI | E49: CARPINTEIRO DE FORMAS COM ENCARGOS COMPLEMENTARES | F49: SEDI - SERVIÇOS DIVERSOS | H49: H | I49: 0.139
B50: Composição Auxiliar | C50: 88316 | D50: SINAPI | E50: SERVENTE COM ENCARGOS COMPLEMENTARES | F50: SEDI - SERVIÇOS DIVERSOS | H50: H | I50: 0.626
B51: Composição Auxiliar | C51: 90587 | D51: SINAPI | E51: VIBRADOR DE IMERSÃO, DIÂMETRO DE PONTEIRA 45MM, MOTOR ELÉTRICO TRIFÁSICO POTÊNCIA DE 2 CV - CHI DIURNO. AF_06/2015 | F51: CHOR - CUSTOS HORÁRIOS DE MÁQUINAS E EQUIPAMENTOS | H51: CHI | I51: 0.071
B52: Composição Auxiliar | C52: 90586 | D52: SINAPI | E52: VIBRADOR DE IMERSÃO, DIÂMETRO DE PONTEIRA 45MM, MOTOR ELÉTRICO TRIFÁSICO POTÊNCIA DE 2 CV - CHP DIURNO. AF_06/2015 | F52: CHOR - CUSTOS HORÁRIOS DE MÁQUINAS E EQUIPAMENTOS | H52: CHP | I52: 0.068
B53: Insumo | C53: 00011145 | D53: SINAPI | E53: CONCRETO USINADO BOMBEAVEL, CLASSE DE RESISTENCIA C35, BRITA 0 E 1, SLUMP = 100 +/- 20 MM, COM BOMBEAMENTO (DISPONIBILIZACAO DE BOMBA), SEM O LANCAMENTO (NBR 8953) | F53: Material | H53: M³ | I53: 1.11
...

Sheet BDI DESONERADO
B2: BONIFICAÇÕES E DESPESAS INDIRETAS
B8: ='DADOS GERAIS'!B8 -> Secretaria de Atenção Especializada à Saúde | D8: BDI Geral: | E8: Encargo Social Mensalista: | F8: ='DADOS GERAIS'!$B$22 -> Data:
B9: ='DADOS GERAIS'!B9 -> Policlínica - Área Construída: 3.213,00 m² | D9: ='DADOS GERAIS'!C19 -> 0.24875249 | E9: ='ENCARGOS SOCIAIS'!F56 -> 0.4757 | F9: ='DADOS GERAIS'!$C$22 -> 09/05/2024
B11: ='DADOS GERAIS'!B11 -> Bancos: | D11: BDI Equipamentos: | E11: Encargo Social Horista: | F11: ='DADOS GERAIS'!$B$23 -> Revisão:
B12: ='DADOS GERAIS'!B12 -> SINAPI (11/2023) - CPOS/CDHU (11/2023) - SBC (11/2023) - ORSE (11/2023) - SEINFRA (028) - IOPES (11/2023) - CAERN (11/2023) - EMOP (11/2023) | D12: ='DADOS GERAIS'!C20 -> 0.16857591 | E12: ='ENCARGOS SOCIAIS'!E56 -> 0.8555518 | F12: ='DADOS GERAIS'!$C$23 -> 03
B15: Fórmula (Bonificações e Despesas Indiretas):
B22: ITEM | C22: DESCRIÇÃO | D22: CÓD | E22: GERAL VALORES PROPOSTOS (%) | F22: EQUIPAMENTOS VALORES PROPOSTOS (%)
B25: 1 | C25: Administração Central | D25: AC | E25: 0.03 | F25: 0.015
B26: 2 | C26: Riscos | D26: R | E26: 0.0127 | F26: 0.0085
B27: 3 | C27: Seguros e Garantias | D27: SG | E27: 0.008 | F27: 0.0048
B28: 4 | C28: Despesas Financeiras | D28: DF | E28: 0.0059 | F28: 0.0085
B29: 5 | C29: Lucro | D29: L | E29: 0.0616 | F29: 0.035
B30: 6 | C30: Impostos | D30: I | E30: =SUM(E31:E34) -> 0.1015 | F30: =SUM(F31:F34) -> 0.0815
B31: 6.1 | C31: PIS | E31: 0.0065 | F31: 0.0065
B32: 6.2 | C32: COFINS | E32: 0.03 | F32: 0.03
B33: 6.3 | C33: ISSQN | E33: 0.02 | F33: 0
B34: 6.4 | C34: CPRB | E34: 0.045 | F34: 0.045
B36: BDI | E36: =((1+E25+E26+E27)*(1+E28)*(1+E29)/(1-E30))-1 -> 0.24875249 | F36: =((1+F25+F26+F27)*(1+F28)*(1+F29)/(1-F30))-1 -> 0.16857591
B39: FONTE:
B40: 1. | C40: Tribunal de Contas da União - TC 036.076/2011-2 - Acórdão Nº 2622/2013
B41: 2. | C41: ISS conforme a Lei Complementar 116/2003 e a Lei 11.438/1997 da Prefeitura Municipal de São Paulo.
B42: 3. | C42: O valor do CPRB foi considerado baseado na Instrução Normativa nº 2053, de 6 de Dezembro de 2021, onde desde Dezembro de 2015 o percentual passa a ser 4,5% e não mais 2,0%. Essa recomendação aplica-se para orçamentos de Construção Civil para os enquadrados nos grupos 412, 432, 433 e 439 da CNAE 2.0. A edificação objeto desta composição se enquadra no grupo 412:4120-4/00 - CLINICAS, HOSPITAIS, CONSTRUÇÃO OU REFORMA.
B44: NOTAS:
B45: 1. | C45: Deverão ser obedecidas as legislações trabalhistas e tributária vigentes, inclusive acordos de classes, sob pena de desclassificação da Proposta de Preços;
B46: 2. | C46: É de responsabilidade da proponente a adequação de todas as fórmulas utilizadas na planilha orçamentária.
B48: ________________________________________________________________________________
B52: ='DADOS GERAIS'!C24 -> Thaís Ferreira Pellaquim
B53: ='DADOS GERAIS'!C25 -> Engenheira Civil - CREA MG 247749/D

Sheet ENCARGOS SOCIAIS
B2: COMPOSIÇÃO ANALÍTICA DAS TAXAS DE ENCARGOS SOCIAIS
B8: ='DADOS GERAIS'!B8 -> Secretaria de Atenção Especializada à Saúde | D8: BDI Geral: | E8: Encargo Social Mensalista: | F8: ='DADOS GERAIS'!$B$22 -> Data:
B9: ='DADOS GERAIS'!B9 -> Policlínica - Área Construída: 3.213,00 m² | D9: ='DADOS GERAIS'!C19 -> 0.24875249 | E9: ='ENCARGOS SOCIAIS'!F56 -> 0.4757 | F9: ='DADOS GERAIS'!$C$22 -> 09/05/2024
B11: ='DADOS GERAIS'!B11 -> Bancos: | D11: BDI Equipamentos: | E11: Encargo Social Horista: | F11: ='DADOS GERAIS'!$B$23 -> Revisão:
B12: ='DADOS GERAIS'!B12 -> SINAPI (11/2023) - CPOS/CDHU (11/2023) - SBC (11/2023) - ORSE (11/2023) - SEINFRA (028) - IOPES (11/2023) - CAERN (11/2023) - EMOP (11/2023) | D12: ='DADOS GERAIS'!C20 -> 0.16857591 | E12: ='ENCARGOS SOCIAIS'!E56 -> 0.8555518 | F12: ='DADOS GERAIS'!$C$23 -> 03
B15: ENCARGOS SOCIAIS SOBRE A MÃO DE OBRA
B16: CÓDIGO | C16: DESCRIÇÃO | E16: COM DESONERAÇÃO
E17: HORISTA (%) | F17: MENSALISTA (%)
B19: GRUPO A
B20: A1 | C20: INSS | E20: 0 | F20: 0
B21: A2 | C21: SESI | E21: 0.015 | F21: 0.015
B22: A3 | C22: SENAI | E22: 0.01 | F22: 0.01
B23: A4 | C23: INCRA | E23: 0.002 | F23: 0.002
B24: A5 | C24: SEBRAE | E24: 0.006 | F24: 0.006
B25: A6 | C25: Salário Educação | E25: 0.025 | F25: 0.025
B26: A7 | C26: Seguro Contra Acidentes de Trabalho | E26: 0.03 | F26: 0.03
B27: A8 | C27: FGTS | E27: 0.08 | F27: 0.08
B28: A9 | C28: SECONCI | E28: 0.01 | F28: 0.01
B29: A | C29: Total | E29: =SUBTOTAL(9,E20:E28) -> 0.178 | F29: =SUBTOTAL(9,F20:F28) -> 0.178
B31: GRUPO B
B32: B1 | C32: Repouso Semanal Remunerado | E32: 0.1798 | F32: Não incide
B33: B2 | C33: Feriados | E33: 0.0469 | F33: Não incide
B34: B3 | C34: Auxílio-Enfermidade | E34: 0.0087 | F34: 0.0066
B35: B4 | C35: 13º Salário | E35: 0.1104 | F35: 0.0833
B36: B5 | C36: Licença Paternidade | E36: 0.0007 | F36: 0.0005
B37: B6 | C37: Faltas Justificadas | E37: 0.0074 | F37: 0.0056
B38: B7 | C38: Dias de Chuva | E38: 0.0135 | F38: Não incide
B39: B8 | C39: Auxílo Acidente de Trabalho | E39: 0.0011 | F39: 0.0008
B40: B9 | C40: Férias Gozadas | E40: 0.1151 | F40: 0.0868
B41: B10 | C41: Salário Maternidade | E41: 0.0004 | F41: 0.0003
B42: B | C42: Total | E42: =SUBTOTAL(9,E32:E41) -> 0.484 | F42: =SUBTOTAL(9,F32:F41) -> 0.1839
B44: GRUPO C
B45: C1 | C45: Aviso Prévio Indenizado | E45: 0.0482 | F45: 0.0364
B46: C2 | C46: Aviso Prévio Trabalhado | E46: 0.0011 | F46: 0.0009
B47: C3 | C47: Férias Indenizadas | E47: 0.0229 | F47: 0.0173
B48: C4 | C48: Depósito Recisão sem justa causa | E48: 0.027 | F48: 0.0203
B49: C5 | C49: Indenização Adicional | E49: 0.0041 | F49: 0.0031
B50: C | C50: Total | E50: =SUBTOTAL(9,E45:E49) -> 0.1033 | F50: =SUBTOTAL(9,F45:F49) -> 0.078
B52: GRUPO D
B53: D1 | C53: Reincidência de Grupo A sobre Grupo B | E53: =ROUND(E42*E29,4) -> 0.0862 | F53: =ROUND(F42*F29,4) -> 0.0327
...

Sheet JUSTIFICATIVAS CPUS
B2: JUSTIFICATIVAS DE COMPOSIÇÕES DE PREÇO UNITÁRIO
B8: ='DADOS GERAIS'!B8 -> Secretaria de Atenção Especializada à Saúde | H8: BDI Geral: | I8: Encargo Social Mensalista: | J8: ='DADOS GERAIS'!$B$22 -> Data:
B9: ='DADOS GERAIS'!B9 -> Policlínica - Área Construída: 3.213,00 m² | H9: ='DADOS GERAIS'!C19 -> 0.24875249 | I9: ='ENCARGOS SOCIAIS'!F56 -> 0.4757 | J9: ='DADOS GERAIS'!$C$22 -> 09/05/2024
B11: ='DADOS GERAIS'!B11 -> Bancos: | H11: BDI Equipamentos: | I11: Encargo Social Horista: | J11: ='DADOS GERAIS'!$B$23 -> Revisão:
B12: ='DADOS GERAIS'!B12 -> SINAPI (11/2023) - CPOS/CDHU (11/2023) - SBC (11/2023) - ORSE (11/2023) - SEINFRA (028) - IOPES (11/2023) - CAERN (11/2023) - EMOP (11/2023) | H12: ='DADOS GERAIS'!C20 -> 0.16857591 | I12: ='ENCARGOS SOCIAIS'!E56 -> 0.8555518 | J12: ='DADOS GERAIS'!$C$23 -> 03
B15: ITEM | C15: COMPOSIÇÃO | D15: COMPOSIÇÃO DE REFERÊNCIA | E15: JUSTIFICATIVA
B16: 1 | C16: 02.02.150 | D16: CPOS/CDHU 02.02.150 | E16: Utilizada composição do CPOS para São Paulo visto que o SINAPI não possui composição adequada para contemplar tal serviço.
B17: 2 | C17: 02.02.130 | D17: CPOS/CDHU 02.02.130 | E17: Utilizada composição do CPOS para São Paulo visto que o SINAPI não possui composição adequada para contemplar tal serviço.
B18: 3 | C18: 02.02.160 | D18: CPOS/CDHU 02.02.160 | E18: Utilizada composição do CPOS para São Paulo visto que o SINAPI não possui composição adequada para contemplar tal serviço.
B19: 4 | C19: 02.02.140 | D19: CPOS/CDHU 02.02.140 | E19: Utilizada composição do CPOS para São Paulo visto que o SINAPI não possui composição adequada para contemplar tal serviço.
B20: 5 | C20: 05.07.040 | D20: CPOS/CDHU 05.07.040 | E20: Utilizada composição do CPOS para São Paulo visto que o SINAPI não possui composição adequada para contemplar tal serviço.
B21: 6 | C21: 012689 | D21: SBC 012689 | E21: Utilizada composição do SBC para São Paulo visto que o SINAPI não possui composição adequada para contemplar tal serviço.
B22: 7 | C22: 021101 | D22: SBC 021101 | E22: Utilizada composição do SBC para São Paulo visto que o SINAPI não possui composição adequada para contemplar tal serviço.
B23: 8 | C23: CPU1926 | D23: SINAPI 97063 + INSUMO SINAPI 20193 | E23: Junção do insumo de locação de andaime m2xmês com a montagem e desmontagem do andaime em m2, sendo coeficiente de 0,416 que corresponde à 1m2 em proporção à área do andaime informado no insumo.
B24: 9 | C24: CPU2096 | D24: Próprio CPU2096 | E24: Substituição do insumo SINAPI 00001525 pelo insumo SINAPI 00011145 para adequação da composição, conforme especificação de projeto.
B25: 10 | C25: 000128 | D25: SBC 000128 | E25: Utilizada composição do SBC para São Paulo visto que o SINAPI não possui composição adequada para contemplar tal serviço.
B26: 11 | C26: CPU2097 | D26: Próprio CPU2097 | E26: Substituição do insumo SINAPI 00001527 pelo insumo SINAPI 00011145 para adequação da composição, conforme especificação de projeto.
B27: 12 | C27: CPU2098 | D27: Próprio CPU2098 | E27: Substituição do insumo SINAPI 00038408 pelo insumo SINAPI 00011145 para adequação da composição, conforme especificação de projeto.
... B270: 255 | C270: 2451 | D270: ORSE 2451 | E270: Utilizada composição do ORSE visto que o SINAPI não possui composição adequada referente a esse serviço. Os preços praticados para esse serviço no estado de Sergipe são referenciais e exequíveis para o orçamento em São Paulo. Os insumos da composição ORSE que são SINAPI estão atualizados para o estado de São Paulo, portanto, somente insumos do ORSE que mantem preço na região de Sergipe.
